[2025-04-06T04:31:46.561+0000] {local_task_job_runner.py:123} INFO - ::group::Pre task execution logs
[2025-04-06T04:31:46.573+0000] {taskinstance.py:2614} INFO - Dependencies all met for dep_context=non-requeueable deps ti=<TaskInstance: redfin_analytics_dag.task_load_to_s3 manual__2025-04-06T04:29:54.408387+00:00 [queued]>
[2025-04-06T04:31:46.578+0000] {taskinstance.py:2614} INFO - Dependencies all met for dep_context=requeueable deps ti=<TaskInstance: redfin_analytics_dag.task_load_to_s3 manual__2025-04-06T04:29:54.408387+00:00 [queued]>
[2025-04-06T04:31:46.579+0000] {taskinstance.py:2867} INFO - Starting attempt 3 of 3
[2025-04-06T04:31:46.590+0000] {taskinstance.py:2890} INFO - Executing <Task(BashOperator): task_load_to_s3> on 2025-04-06 04:29:54.408387+00:00
[2025-04-06T04:31:46.595+0000] {standard_task_runner.py:72} INFO - Started process 5050 to run task
[2025-04-06T04:31:46.598+0000] {standard_task_runner.py:104} INFO - Running: ['airflow', 'tasks', 'run', 'redfin_analytics_dag', 'task_load_to_s3', 'manual__2025-04-06T04:29:54.408387+00:00', '--job-id', '24', '--raw', '--subdir', 'DAGS_FOLDER/redfin_dags.py', '--cfg-path', '/tmp/tmp3p9s_lyb']
[2025-04-06T04:31:46.599+0000] {standard_task_runner.py:105} INFO - Job 24: Subtask task_load_to_s3
[2025-04-06T04:31:46.785+0000] {task_command.py:467} INFO - Running <TaskInstance: redfin_analytics_dag.task_load_to_s3 manual__2025-04-06T04:29:54.408387+00:00 [running]> on host ip-172-31-10-23.ap-southeast-2.compute.internal
[2025-04-06T04:31:46.831+0000] {taskinstance.py:3134} INFO - Exporting env vars: AIRFLOW_CTX_DAG_OWNER='airflow' AIRFLOW_CTX_DAG_ID='redfin_analytics_dag' AIRFLOW_CTX_TASK_ID='task_load_to_s3' AIRFLOW_CTX_EXECUTION_DATE='2025-04-06T04:29:54.408387+00:00' AIRFLOW_CTX_TRY_NUMBER='3' AIRFLOW_CTX_DAG_RUN_ID='manual__2025-04-06T04:29:54.408387+00:00'
[2025-04-06T04:31:46.832+0000] {taskinstance.py:732} INFO - ::endgroup::
[2025-04-06T04:31:46.841+0000] {subprocess.py:78} INFO - Tmp dir root location: /tmp
[2025-04-06T04:31:46.841+0000] {subprocess.py:88} INFO - Running command: ['/usr/bin/bash', '-c', 'aws s3 mv/home/ubuntu/redfin_data_20250406-043101.csv s3//redfin-data-bucket-gista']
[2025-04-06T04:31:46.851+0000] {subprocess.py:99} INFO - Output:
[2025-04-06T04:31:47.194+0000] {subprocess.py:106} INFO - usage: Note: AWS CLI version 2, the latest major version of the AWS CLI, is now stable and recommended for general use. For more information, see the AWS CLI version 2 installation instructions at: https://docs.aws.amazon.com/cli/latest/userguide/install-cliv2.html
[2025-04-06T04:31:47.194+0000] {subprocess.py:106} INFO - 
[2025-04-06T04:31:47.195+0000] {subprocess.py:106} INFO - usage: aws [options] <command> <subcommand> [<subcommand> ...] [parameters]
[2025-04-06T04:31:47.195+0000] {subprocess.py:106} INFO - To see help text, you can run:
[2025-04-06T04:31:47.195+0000] {subprocess.py:106} INFO - 
[2025-04-06T04:31:47.195+0000] {subprocess.py:106} INFO -   aws help
[2025-04-06T04:31:47.196+0000] {subprocess.py:106} INFO -   aws <command> help
[2025-04-06T04:31:47.196+0000] {subprocess.py:106} INFO -   aws <command> <subcommand> help
[2025-04-06T04:31:47.196+0000] {subprocess.py:106} INFO - aws: error: argument subcommand: Invalid choice, valid choices are:
[2025-04-06T04:31:47.197+0000] {subprocess.py:106} INFO - 
[2025-04-06T04:31:47.197+0000] {subprocess.py:106} INFO - ls                                       | website
[2025-04-06T04:31:47.197+0000] {subprocess.py:106} INFO - cp                                       | mv
[2025-04-06T04:31:47.197+0000] {subprocess.py:106} INFO - rm                                       | sync
[2025-04-06T04:31:47.198+0000] {subprocess.py:106} INFO - mb                                       | rb
[2025-04-06T04:31:47.198+0000] {subprocess.py:106} INFO - presign
[2025-04-06T04:31:47.242+0000] {subprocess.py:110} INFO - Command exited with return code 2
[2025-04-06T04:31:47.249+0000] {taskinstance.py:3313} ERROR - Task failed with exception
Traceback (most recent call last):
  File "/home/ubuntu/venv/lib/python3.12/site-packages/airflow/models/taskinstance.py", line 768, in _execute_task
    result = _execute_callable(context=context, **execute_callable_kwargs)
             ^^^^^^^^^^^^^^^^^^^^^^^^^^^^^^^^^^^^^^^^^^^^^^^^^^^^^^^^^^^^^
  File "/home/ubuntu/venv/lib/python3.12/site-packages/airflow/models/taskinstance.py", line 734, in _execute_callable
    return ExecutionCallableRunner(
           ^^^^^^^^^^^^^^^^^^^^^^^^
  File "/home/ubuntu/venv/lib/python3.12/site-packages/airflow/utils/operator_helpers.py", line 252, in run
    return self.func(*args, **kwargs)
           ^^^^^^^^^^^^^^^^^^^^^^^^^^
  File "/home/ubuntu/venv/lib/python3.12/site-packages/airflow/models/baseoperator.py", line 424, in wrapper
    return func(self, *args, **kwargs)
           ^^^^^^^^^^^^^^^^^^^^^^^^^^^
  File "/home/ubuntu/venv/lib/python3.12/site-packages/airflow/operators/bash.py", line 276, in execute
    raise AirflowException(
airflow.exceptions.AirflowException: Bash command failed. The command returned a non-zero exit code 2.
[2025-04-06T04:31:47.254+0000] {taskinstance.py:1226} INFO - Marking task as FAILED. dag_id=redfin_analytics_dag, task_id=task_load_to_s3, run_id=manual__2025-04-06T04:29:54.408387+00:00, execution_date=20250406T042954, start_date=20250406T043146, end_date=20250406T043147
[2025-04-06T04:31:47.273+0000] {taskinstance.py:341} INFO - ::group::Post task execution logs
[2025-04-06T04:31:47.273+0000] {standard_task_runner.py:124} ERROR - Failed to execute job 24 for task task_load_to_s3 (Bash command failed. The command returned a non-zero exit code 2.; 5050)
Traceback (most recent call last):
  File "/home/ubuntu/venv/lib/python3.12/site-packages/airflow/task/task_runner/standard_task_runner.py", line 117, in _start_by_fork
    ret = args.func(args, dag=self.dag)
          ^^^^^^^^^^^^^^^^^^^^^^^^^^^^^
  File "/home/ubuntu/venv/lib/python3.12/site-packages/airflow/cli/cli_config.py", line 49, in command
    return func(*args, **kwargs)
           ^^^^^^^^^^^^^^^^^^^^^
  File "/home/ubuntu/venv/lib/python3.12/site-packages/airflow/utils/cli.py", line 116, in wrapper
    return f(*args, **kwargs)
           ^^^^^^^^^^^^^^^^^^
  File "/home/ubuntu/venv/lib/python3.12/site-packages/airflow/cli/commands/task_command.py", line 483, in task_run
    task_return_code = _run_task_by_selected_method(args, _dag, ti)
                       ^^^^^^^^^^^^^^^^^^^^^^^^^^^^^^^^^^^^^^^^^^^^
  File "/home/ubuntu/venv/lib/python3.12/site-packages/airflow/cli/commands/task_command.py", line 256, in _run_task_by_selected_method
    return _run_raw_task(args, ti)
           ^^^^^^^^^^^^^^^^^^^^^^^
  File "/home/ubuntu/venv/lib/python3.12/site-packages/airflow/cli/commands/task_command.py", line 341, in _run_raw_task
    return ti._run_raw_task(
           ^^^^^^^^^^^^^^^^^
  File "/home/ubuntu/venv/lib/python3.12/site-packages/airflow/utils/session.py", line 97, in wrapper
    return func(*args, session=session, **kwargs)
           ^^^^^^^^^^^^^^^^^^^^^^^^^^^^^^^^^^^^^^
  File "/home/ubuntu/venv/lib/python3.12/site-packages/airflow/models/taskinstance.py", line 3006, in _run_raw_task
    return _run_raw_task(
           ^^^^^^^^^^^^^^
  File "/home/ubuntu/venv/lib/python3.12/site-packages/airflow/models/taskinstance.py", line 274, in _run_raw_task
    TaskInstance._execute_task_with_callbacks(
  File "/home/ubuntu/venv/lib/python3.12/site-packages/airflow/models/taskinstance.py", line 3161, in _execute_task_with_callbacks
    result = self._execute_task(context, task_orig)
             ^^^^^^^^^^^^^^^^^^^^^^^^^^^^^^^^^^^^^^
  File "/home/ubuntu/venv/lib/python3.12/site-packages/airflow/models/taskinstance.py", line 3185, in _execute_task
    return _execute_task(self, context, task_orig)
           ^^^^^^^^^^^^^^^^^^^^^^^^^^^^^^^^^^^^^^^
  File "/home/ubuntu/venv/lib/python3.12/site-packages/airflow/models/taskinstance.py", line 768, in _execute_task
    result = _execute_callable(context=context, **execute_callable_kwargs)
             ^^^^^^^^^^^^^^^^^^^^^^^^^^^^^^^^^^^^^^^^^^^^^^^^^^^^^^^^^^^^^
  File "/home/ubuntu/venv/lib/python3.12/site-packages/airflow/models/taskinstance.py", line 734, in _execute_callable
    return ExecutionCallableRunner(
           ^^^^^^^^^^^^^^^^^^^^^^^^
  File "/home/ubuntu/venv/lib/python3.12/site-packages/airflow/utils/operator_helpers.py", line 252, in run
    return self.func(*args, **kwargs)
           ^^^^^^^^^^^^^^^^^^^^^^^^^^
  File "/home/ubuntu/venv/lib/python3.12/site-packages/airflow/models/baseoperator.py", line 424, in wrapper
    return func(self, *args, **kwargs)
           ^^^^^^^^^^^^^^^^^^^^^^^^^^^
  File "/home/ubuntu/venv/lib/python3.12/site-packages/airflow/operators/bash.py", line 276, in execute
    raise AirflowException(
airflow.exceptions.AirflowException: Bash command failed. The command returned a non-zero exit code 2.
[2025-04-06T04:31:47.294+0000] {local_task_job_runner.py:266} INFO - Task exited with return code 1
[2025-04-06T04:31:47.307+0000] {taskinstance.py:3901} INFO - 0 downstream tasks scheduled from follow-on schedule check
[2025-04-06T04:31:47.308+0000] {local_task_job_runner.py:245} INFO - ::endgroup::
